source install/setup.bash
colcon build --symlink-install
ros2 launch my_bot launch_sim.launch.py

ros2 launch my_bot rsp.launch.py
rviz2

ros2 run joint_state_publisher_gui joint_state_publisher_gui
ros2 launch my_bot rsp.launch.py use_sim_time:=true
ros2 launch gazebo_ros gazebo.launch.py
ros2 run gazebo_ros spawn_entity.py -topic robot_description -entity robot_name
ros2 launch my_bot launch_sim.launch.py
ros2 run teleop_twist_keyboard teleop_twist_keyboard

git status
git add .
git status
git commit -m "Updated skid steer NOW WORKING!!($(date))"
git push -u origin main


<?xml version="1.0"?>
<robot xmlns:xacro="http://www.ros.org/wiki/xacro">

    <gazebo>
        <plugin name="skid_steer_drive_controller" filename="libgazebo_ros_skid_steer_drive.so">
            <updateRate>10.0</updateRate>
            <robotNamespace>/robot</robotNamespace>
            <leftFrontJoint>left_front_wheel_joint</leftFrontJoint>
            <rightFrontJoint>right_front_wheel_joint</rightFrontJoint>
            <leftRearJoint>left_rear_wheel_joint</leftRearJoint>
            <rightRearJoint>right_rear_wheel_joint</rightRearJoint>
            <wheelSeparation>0.4</wheelSeparation>
            <wheelDiameter>0.2</wheelDiameter>
            <robotBaseFrame>base_link</robotBaseFrame>
            <torque>10</torque>

            <topicName>cmd_vel</topicName>
            <odometryTopic>odom</odometryTopic>
            <odometryFrame>odom</odometryFrame>

            <commandTopic>cmd_vel</commandTopic>
            <topic_name_twist>cmd_vel</topic_name_twist>
            <topic_name_odometry>odom</topic_name_odometry>
            <topic_name_joint>joint</topic_name_joint>

            <broadcastTF>true</broadcastTF>

            <covariance_x>0.0001</covariance_x>
            <covariance_y>0.0001</covariance_y>
            <covariance_yaw>0.01</covariance_yaw>

        </plugin>
     </gazebo>


</robot>

<?xml version="1.0"?>
<robot xmlns:xacro="http://www.ros.org/wiki/xacro">

    <gazebo>
        <plugin name="skid_steer_drive_controller" filename="libgazebo_ros_skid_steer_drive.so">
    
            <updateRate>10.0</updateRate>
            <robotNamespace>/</robotNamespace>
            <!-- Wheel Information -->
            <leftFrontJoint>left_front_wheel_joint</leftFrontJoint>
            <rightFrontJoint>right_front_wheel_joint</rightFrontJoint>
            <leftRearJoint>left_rear_wheel_joint</leftRearJoint>
            <rightRearJoint>right_rear_wheel_joint</rightRearJoint>
    
            <wheelSeparation>0.4</wheelSeparation>
            <wheelDiameter>0.7</wheelDiameter>
            
            <robotBaseFrame>base_link</robotBaseFrame>
            <torque>10</torque>
            <topicName>cmd_vel</topicName>
            <odometryTopic>odom</odometryTopic>
            <odometryFrame>odom</odometryFrame>

            <commandTopic>cmd_vel</commandTopic>
            <topic_name_twist>cmd_vel</topic_name_twist>
            <topic_name_odometry>odom</topic_name_odometry>
            <topic_name_joint>joint</topic_name_joint>
            <broadcastTF>true</broadcastTF>

            <covarience_x>0.0001</covarience_x>
            <covarience_y>0.0001</covarience_y>
            <covarience_yaw>0.01</covarience_yaw>
        </plugin>
    </gazebo>

</robot>

//original
<?xml version="1.0"?>
<robot xmlns:xacro="http://www.ros.org/wiki/xacro">

    <gazebo>
        <plugin name='diff_drive' filename='libgazebo_ros_diff_drive.so'>
    
    
            <!-- Wheel Information -->
            <left_joint>left_front_wheel_joint</left_joint>
            <right_joint>right_front_wheel_joint</right_joint>
            <left_rear_joint>left_rear_wheel_joint</left_rear_joint>
            <right_rear_joint>right_rear_wheel_joint</right_rear_joint>
    
            <!-- Wheel Separation and Diameter -->
            <wheel_separation>0.1</wheel_separation> 
            <wheel_diameter>0.07</wheel_diameter>      
    
            <!-- Limits -->
            <max_wheel_torque>200</max_wheel_torque>
            <max_wheel_acceleration>10.0</max_wheel_acceleration>
    
            <!-- Output -->
            <odometry_frame>odom</odometry_frame>
            <robot_base_frame>base_link</robot_base_frame>
    
            <publish_odom>true</publish_odom>
            <publish_odom_tf>true</publish_odom_tf>
            <publish_wheel_tf>true</publish_wheel_tf>
    
        </plugin>
    </gazebo>

</robot>

diff drive code

<?xml version="1.0"?>
<robot xmlns:xacro="http://www.ros.org/wiki/xacro">

    <xacro:include filename="inertial_macros.xacro"/>

    <material name="white">
        <color rgba="1 1 1 1" />
    </material>

    <material name="blue">
        <color rgba="0.2 0.2 1 1"/>
    </material>

    <material name="black">
        <color rgba="0 0 0 1"/>
    </material>

    <!-- BASE LINK -->

    <link name="base_link">

    </link>

    <!-- CHASSIS LINK -->

    <joint name="chassis_joint" type="fixed">
        <parent link="base_link"/>
        <child link="chassis"/>
        <origin xyz="-0.13 0 0"/>
    </joint>

    <link name="chassis">
        <visual>
            <origin xyz="0.128 0 0"/>
            <geometry>
                <box size="0.256 0.15 0.035"/>
            </geometry>
            <material name="white"/>
        </visual>
        <collision>
            <origin xyz="0 0 0"/>
            <geometry>
                <box size="0.256 0.15 0.035"/>
            </geometry>
        </collision>
        <xacro:inertial_box mass="0.5" x="0.254" y="0.1524" z="0.15">
            <origin xyz="0.128 0 0" rpy="0 0 0"/>
        </xacro:inertial_box>
    </link>

    <gazebo reference="chassis">
        <material>Gazebo/White</material>
    </gazebo>

    <!-- LEFT FRONT WHEEL LINK -->

    <joint name="left_front_wheel_joint" type="continuous">
        <parent link="base_link"/>
        <child link="left_front_wheel"/>
        <origin xyz="0.06 0.065 0" rpy="-${pi/2} 0 0" />
        <axis xyz="0 0 1"/>
    </joint>

    <link name="left_front_wheel">
        <visual>
            <geometry>
                <cylinder radius="0.035" length="0.025"/>
            </geometry>
            <material name="blue"/>
        </visual>
        <collision>
            <geometry>
                <cylinder radius="0.035" length="0.025"/>
            </geometry>
        </collision>
        <xacro:inertial_cylinder mass="0.1" length="0.025" radius="0.035">
            <origin xyz="0 0 0" rpy="1.5708 0 0"/>
        </xacro:inertial_cylinder>
    </link>

    <gazebo reference="left_front_wheel">
        <material>Gazebo/Blue</material>
    </gazebo>

    <!-- RIGHT FRONT WHEEL LINK -->

    <joint name="right_front_wheel_joint" type="continuous">
        <parent link="base_link"/>
        <child link="right_front_wheel"/>
        <origin xyz="0.06 -0.065 0" rpy="${pi/2} 0 0" />
        <axis xyz="0 0 -1"/>
    </joint>

    <link name="right_front_wheel">
        <visual>
            <geometry>
                <cylinder radius="0.035" length="0.025"/>
            </geometry>
            <material name="blue"/>
        </visual>
        <collision>
            <geometry>
                <cylinder radius="0.035" length="0.025"/>
            </geometry>
        </collision>
        <xacro:inertial_cylinder mass="0.1" length="0.025" radius="0.035">
            <origin xyz="0 0 0" rpy="1.5708 0 0"/>
        </xacro:inertial_cylinder>
    </link>

    <gazebo reference="right_front_wheel">
        <material>Gazebo/Blue</material>
    </gazebo>

    <!-- LEFT REAR WHEEL LINK -->

    <joint name="left_rear_wheel_joint" type="continuous">
        <parent link="base_link"/>
        <child link="left_rear_wheel"/>
        <origin xyz="-0.06 0.065 0" rpy="-${pi/2} 0 0" />
        <axis xyz="0 0 1"/>
    </joint>

    <link name="left_rear_wheel">
        <visual>
            <geometry>
                <cylinder radius="0.035" length="0.025"/>
            </geometry>
            <material name="blue"/>
        </visual>
        <collision>
            <geometry>
                <cylinder radius="0.035" length="0.025"/>
            </geometry>
        </collision>
        <xacro:inertial_cylinder mass="0.1" length="0.025" radius="0.035">
            <origin xyz="0 0 0" rpy="1.5708 0 0"/>
        </xacro:inertial_cylinder>
    </link>

    <gazebo reference="left_rear_wheel">
        <material>Gazebo/Blue</material>
    </gazebo>

    <!-- RIGHT REAR WHEEL LINK -->

    <joint name="right_rear_wheel_joint" type="continuous">
        <parent link="base_link"/>
        <child link="right_rear_wheel"/>
        <origin xyz="-0.06 -0.065 0" rpy="${pi/2} 0 0" />
        <axis xyz="0 0 -1"/>
    </joint>

    <link name="right_rear_wheel">
        <visual>
            <geometry>
                <cylinder radius="0.035" length="0.025"/>
            </geometry>
            <material name="blue"/>
        </visual>
        <collision>
            <geometry>
                <cylinder radius="0.035" length="0.025"/>
            </geometry>
        </collision>
        <xacro:inertial_cylinder mass="0.1" length="0.025" radius="0.035">
            <origin xyz="0 0 0" rpy="1.5708 0 0"/>
        </xacro:inertial_cylinder>
    </link>

    <gazebo reference="right_rear_wheel">
        <material>Gazebo/Blue</material>
    </gazebo>

</robot>
